2024-04-11 10:34:31,589 INFO    StreamThr :5608 [internal.py:wandb_internal():86] W&B internal server running at pid: 5608, started at: 2024-04-11 10:34:31.588168
2024-04-11 10:34:31,590 DEBUG   HandlerThread:5608 [handler.py:handle_request():146] handle_request: status
2024-04-11 10:34:31,593 INFO    WriterThread:5608 [datastore.py:open_for_write():87] open: E:\JD_PROJECT\project\ClassyVision\wandb\run-20240411_103431-657cbhcr\run-657cbhcr.wandb
2024-04-11 10:34:31,594 DEBUG   SenderThread:5608 [sender.py:send():379] send: header
2024-04-11 10:34:31,595 DEBUG   SenderThread:5608 [sender.py:send():379] send: run
2024-04-11 10:34:31,604 INFO    SenderThread:5608 [sender.py:_setup_resume():749] checking resume status for None/YOLOv5/657cbhcr
2024-04-11 10:34:32,756 INFO    SenderThread:5608 [dir_watcher.py:__init__():211] watching files in: E:\JD_PROJECT\project\ClassyVision\wandb\run-20240411_103431-657cbhcr\files
2024-04-11 10:34:32,756 INFO    SenderThread:5608 [sender.py:_start_run_threads():1124] run started: 657cbhcr with start time 1712802871.589165
2024-04-11 10:34:32,764 DEBUG   HandlerThread:5608 [handler.py:handle_request():146] handle_request: check_version
2024-04-11 10:34:32,765 DEBUG   SenderThread:5608 [sender.py:send_request():406] send_request: check_version
2024-04-11 10:34:33,087 DEBUG   HandlerThread:5608 [handler.py:handle_request():146] handle_request: run_start
2024-04-11 10:34:33,106 DEBUG   HandlerThread:5608 [system_info.py:__init__():26] System info init
2024-04-11 10:34:33,106 DEBUG   HandlerThread:5608 [system_info.py:__init__():41] System info init done
2024-04-11 10:34:33,106 INFO    HandlerThread:5608 [system_monitor.py:start():194] Starting system monitor
2024-04-11 10:34:33,106 INFO    SystemMonitor:5608 [system_monitor.py:_start():158] Starting system asset monitoring threads
2024-04-11 10:34:33,107 INFO    HandlerThread:5608 [system_monitor.py:probe():214] Collecting system info
2024-04-11 10:34:33,109 INFO    SystemMonitor:5608 [interfaces.py:start():190] Started cpu monitoring
2024-04-11 10:34:33,110 INFO    SystemMonitor:5608 [interfaces.py:start():190] Started disk monitoring
2024-04-11 10:34:33,111 INFO    SystemMonitor:5608 [interfaces.py:start():190] Started gpu monitoring
2024-04-11 10:34:33,114 INFO    SystemMonitor:5608 [interfaces.py:start():190] Started memory monitoring
2024-04-11 10:34:33,122 INFO    SystemMonitor:5608 [interfaces.py:start():190] Started network monitoring
2024-04-11 10:34:33,128 DEBUG   HandlerThread:5608 [system_info.py:probe():150] Probing system
2024-04-11 10:34:33,129 DEBUG   HandlerThread:5608 [system_info.py:_probe_git():135] Probing git
2024-04-11 10:34:33,129 ERROR   gpu       :5608 [interfaces.py:monitor():144] Failed to sample metric: Not Supported
2024-04-11 10:34:33,129 ERROR   gpu       :5608 [interfaces.py:monitor():144] Failed to sample metric: Not Supported
2024-04-11 10:34:33,159 DEBUG   HandlerThread:5608 [system_info.py:_probe_git():143] Probing git done
2024-04-11 10:34:33,159 DEBUG   HandlerThread:5608 [system_info.py:probe():198] Probing system done
2024-04-11 10:34:33,159 DEBUG   HandlerThread:5608 [system_monitor.py:probe():223] {'os': 'Windows-10-10.0.19045-SP0', 'python': '3.10.14', 'heartbeatAt': '2024-04-11T02:34:33.128637', 'startedAt': '2024-04-11T02:34:31.582184', 'docker': None, 'cuda': None, 'args': (), 'state': 'running', 'program': 'E:\\JD_PROJECT\\project\\ClassyVision\\train.py', 'codePathLocal': 'train.py', 'codePath': 'train.py', 'git': {'remote': None, 'commit': None}, 'email': None, 'root': 'E:/JD_PROJECT/project/ClassyVision', 'host': 'DZA-4CE139BDJQ', 'username': 'Administrator', 'executable': 'D:\\Users\\Administrator\\anaconda3\\envs\\ClassyVision2\\python.exe', 'cpu_count': 8, 'cpu_count_logical': 16, 'cpu_freq': {'current': 2904.0, 'min': 0.0, 'max': 2904.0}, 'cpu_freq_per_core': [{'current': 2904.0, 'min': 0.0, 'max': 2904.0}], 'disk': {'/': {'total': 1745.8271446228027, 'used': 79.63742065429688}}, 'gpu': 'Quadro P1000', 'gpu_count': 1, 'gpu_devices': [{'name': 'Quadro P1000', 'memory_total': 4294967296}], 'memory': {'total': 31.781455993652344}}
2024-04-11 10:34:33,159 INFO    HandlerThread:5608 [system_monitor.py:probe():224] Finished collecting system info
2024-04-11 10:34:33,159 INFO    HandlerThread:5608 [system_monitor.py:probe():227] Publishing system info
2024-04-11 10:34:33,159 DEBUG   HandlerThread:5608 [system_info.py:_save_conda():207] Saving list of conda packages installed into the current environment
2024-04-11 10:34:33,770 INFO    Thread-16 :5608 [dir_watcher.py:_on_file_created():271] file/dir created: E:\JD_PROJECT\project\ClassyVision\wandb\run-20240411_103431-657cbhcr\files\conda-environment.yaml
2024-04-11 10:34:35,146 ERROR   gpu       :5608 [interfaces.py:monitor():144] Failed to sample metric: Not Supported
2024-04-11 10:34:35,146 ERROR   gpu       :5608 [interfaces.py:monitor():144] Failed to sample metric: Not Supported
2024-04-11 10:34:37,161 ERROR   gpu       :5608 [interfaces.py:monitor():144] Failed to sample metric: Not Supported
2024-04-11 10:34:37,161 ERROR   gpu       :5608 [interfaces.py:monitor():144] Failed to sample metric: Not Supported
2024-04-11 10:34:38,291 DEBUG   HandlerThread:5608 [system_info.py:_save_conda():222] Saving conda packages done
2024-04-11 10:34:38,291 INFO    HandlerThread:5608 [system_monitor.py:probe():229] Finished publishing system info
2024-04-11 10:34:38,301 DEBUG   HandlerThread:5608 [handler.py:handle_request():146] handle_request: status_report
2024-04-11 10:34:38,301 DEBUG   HandlerThread:5608 [handler.py:handle_request():146] handle_request: keepalive
2024-04-11 10:34:38,301 DEBUG   SenderThread:5608 [sender.py:send():379] send: files
2024-04-11 10:34:38,301 INFO    SenderThread:5608 [sender.py:_save_file():1390] saving file wandb-metadata.json with policy now
2024-04-11 10:34:38,537 DEBUG   HandlerThread:5608 [handler.py:handle_request():146] handle_request: python_packages
2024-04-11 10:34:38,538 DEBUG   SenderThread:5608 [sender.py:send_request():406] send_request: python_packages
2024-04-11 10:34:38,538 DEBUG   HandlerThread:5608 [handler.py:handle_request():146] handle_request: stop_status
2024-04-11 10:34:38,538 DEBUG   SenderThread:5608 [sender.py:send_request():406] send_request: stop_status
2024-04-11 10:34:38,541 DEBUG   HandlerThread:5608 [handler.py:handle_request():146] handle_request: internal_messages
2024-04-11 10:34:38,799 INFO    Thread-16 :5608 [dir_watcher.py:_on_file_modified():288] file/dir modified: E:\JD_PROJECT\project\ClassyVision\wandb\run-20240411_103431-657cbhcr\files\conda-environment.yaml
2024-04-11 10:34:38,799 INFO    Thread-16 :5608 [dir_watcher.py:_on_file_created():271] file/dir created: E:\JD_PROJECT\project\ClassyVision\wandb\run-20240411_103431-657cbhcr\files\wandb-metadata.json
2024-04-11 10:34:38,800 INFO    Thread-16 :5608 [dir_watcher.py:_on_file_created():271] file/dir created: E:\JD_PROJECT\project\ClassyVision\wandb\run-20240411_103431-657cbhcr\files\requirements.txt
2024-04-11 10:34:39,037 ERROR   wandb-upload_0:5608 [internal_api.py:upload_file():2767] upload_file exception https://storage.googleapis.com/wandb-production.appspot.com/beallhuang/YOLOv5/657cbhcr/wandb-metadata.json?Expires=1712889278&GoogleAccessId=gorilla-files-url-signer-man%40wandb-production.iam.gserviceaccount.com&Signature=km5e88YFw%2BgSlzDE2JKgWzM%2BizNHGVPy7KGY%2BfUXfTyX9uHqllWMVv%2FmDk0TAsvH8Ug81xJKejV%2FLcR1yO3WF6ETKIiyT34ZXlpDeL8B9l%2Bdr9k7irC1O4shi6ae0DGZPCq%2Fy1UeKDJGuHpnzSHWx6fPp46jmY6ePRrq0fN2vI2nGrney0zVGHc7nUC0Xs2HE98S26%2BkJeiOUokSg%2BATmbSY19ZFGLD2z2j9AL0wNJ%2Bo6KC5ZidGl4jINWVYsA7%2FgJoZwxzO7WzvdaYLDOVQJdbI0ABpkcenQmwjSBROgCXp2nX813eL0IJku6PWTiJIuXlx3nAcbnNzQKSBl8nJ6g%3D%3D: ('Connection aborted.', ConnectionResetError(10054, '远程主机强迫关闭了一个现有的连接。', None, 10054, None))
2024-04-11 10:34:39,037 ERROR   wandb-upload_0:5608 [internal_api.py:upload_file():2769] upload_file request headers: {'User-Agent': 'python-requests/2.31.0', 'Accept-Encoding': 'gzip, deflate', 'Accept': '*/*', 'Connection': 'keep-alive', 'Content-Length': '1342'}
2024-04-11 10:34:39,037 ERROR   wandb-upload_0:5608 [internal_api.py:upload_file():2771] upload_file response body: 
2024-04-11 10:34:39,076 DEBUG   SenderThread:5608 [sender.py:send():379] send: telemetry
2024-04-11 10:34:39,172 ERROR   gpu       :5608 [interfaces.py:monitor():144] Failed to sample metric: Not Supported
2024-04-11 10:34:39,172 ERROR   gpu       :5608 [interfaces.py:monitor():144] Failed to sample metric: Not Supported
2024-04-11 10:34:39,808 INFO    Thread-16 :5608 [dir_watcher.py:_on_file_created():271] file/dir created: E:\JD_PROJECT\project\ClassyVision\wandb\run-20240411_103431-657cbhcr\files\output.log
2024-04-11 10:34:40,368 ERROR   wandb-upload_0:5608 [internal_api.py:upload_file():2767] upload_file exception https://storage.googleapis.com/wandb-production.appspot.com/beallhuang/YOLOv5/657cbhcr/wandb-metadata.json?Expires=1712889278&GoogleAccessId=gorilla-files-url-signer-man%40wandb-production.iam.gserviceaccount.com&Signature=km5e88YFw%2BgSlzDE2JKgWzM%2BizNHGVPy7KGY%2BfUXfTyX9uHqllWMVv%2FmDk0TAsvH8Ug81xJKejV%2FLcR1yO3WF6ETKIiyT34ZXlpDeL8B9l%2Bdr9k7irC1O4shi6ae0DGZPCq%2Fy1UeKDJGuHpnzSHWx6fPp46jmY6ePRrq0fN2vI2nGrney0zVGHc7nUC0Xs2HE98S26%2BkJeiOUokSg%2BATmbSY19ZFGLD2z2j9AL0wNJ%2Bo6KC5ZidGl4jINWVYsA7%2FgJoZwxzO7WzvdaYLDOVQJdbI0ABpkcenQmwjSBROgCXp2nX813eL0IJku6PWTiJIuXlx3nAcbnNzQKSBl8nJ6g%3D%3D: ('Connection aborted.', ConnectionResetError(10054, '远程主机强迫关闭了一个现有的连接。', None, 10054, None))
2024-04-11 10:34:40,369 ERROR   wandb-upload_0:5608 [internal_api.py:upload_file():2769] upload_file request headers: {'User-Agent': 'python-requests/2.31.0', 'Accept-Encoding': 'gzip, deflate', 'Accept': '*/*', 'Connection': 'keep-alive', 'Content-Length': '1342'}
2024-04-11 10:34:40,369 ERROR   wandb-upload_0:5608 [internal_api.py:upload_file():2771] upload_file response body: 
2024-04-11 10:34:41,194 ERROR   gpu       :5608 [interfaces.py:monitor():144] Failed to sample metric: Not Supported
2024-04-11 10:34:41,194 ERROR   gpu       :5608 [interfaces.py:monitor():144] Failed to sample metric: Not Supported
2024-04-11 10:34:41,828 INFO    Thread-16 :5608 [dir_watcher.py:_on_file_modified():288] file/dir modified: E:\JD_PROJECT\project\ClassyVision\wandb\run-20240411_103431-657cbhcr\files\output.log
2024-04-11 10:34:42,457 DEBUG   SenderThread:5608 [sender.py:send():379] send: files
2024-04-11 10:34:42,458 INFO    SenderThread:5608 [sender.py:_save_file():1390] saving file media\images\Labels_0_7b7bbe6d6ad3ad4e2a51.jpg with policy now
2024-04-11 10:34:42,458 DEBUG   HandlerThread:5608 [handler.py:handle_request():146] handle_request: status_report
2024-04-11 10:34:42,463 DEBUG   SenderThread:5608 [sender.py:send():379] send: files
2024-04-11 10:34:42,463 INFO    SenderThread:5608 [sender.py:_save_file():1390] saving file media\images\Labels_0_dc702dc1a9f49492fdb7.jpg with policy now
2024-04-11 10:34:42,481 DEBUG   HandlerThread:5608 [handler.py:handle_request():146] handle_request: partial_history
2024-04-11 10:34:42,779 ERROR   wandb-upload_0:5608 [internal_api.py:upload_file():2767] upload_file exception https://storage.googleapis.com/wandb-production.appspot.com/beallhuang/YOLOv5/657cbhcr/wandb-metadata.json?Expires=1712889278&GoogleAccessId=gorilla-files-url-signer-man%40wandb-production.iam.gserviceaccount.com&Signature=km5e88YFw%2BgSlzDE2JKgWzM%2BizNHGVPy7KGY%2BfUXfTyX9uHqllWMVv%2FmDk0TAsvH8Ug81xJKejV%2FLcR1yO3WF6ETKIiyT34ZXlpDeL8B9l%2Bdr9k7irC1O4shi6ae0DGZPCq%2Fy1UeKDJGuHpnzSHWx6fPp46jmY6ePRrq0fN2vI2nGrney0zVGHc7nUC0Xs2HE98S26%2BkJeiOUokSg%2BATmbSY19ZFGLD2z2j9AL0wNJ%2Bo6KC5ZidGl4jINWVYsA7%2FgJoZwxzO7WzvdaYLDOVQJdbI0ABpkcenQmwjSBROgCXp2nX813eL0IJku6PWTiJIuXlx3nAcbnNzQKSBl8nJ6g%3D%3D: ('Connection aborted.', ConnectionResetError(10054, '远程主机强迫关闭了一个现有的连接。', None, 10054, None))
2024-04-11 10:34:42,779 ERROR   wandb-upload_0:5608 [internal_api.py:upload_file():2769] upload_file request headers: {'User-Agent': 'python-requests/2.31.0', 'Accept-Encoding': 'gzip, deflate', 'Accept': '*/*', 'Connection': 'keep-alive', 'Content-Length': '1342'}
2024-04-11 10:34:42,779 ERROR   wandb-upload_0:5608 [internal_api.py:upload_file():2771] upload_file response body: 
2024-04-11 10:34:42,844 INFO    Thread-16 :5608 [dir_watcher.py:_on_file_created():271] file/dir created: E:\JD_PROJECT\project\ClassyVision\wandb\run-20240411_103431-657cbhcr\files\media\images\Labels_0_7b7bbe6d6ad3ad4e2a51.jpg
2024-04-11 10:34:42,844 INFO    Thread-16 :5608 [dir_watcher.py:_on_file_created():271] file/dir created: E:\JD_PROJECT\project\ClassyVision\wandb\run-20240411_103431-657cbhcr\files\media\images\Labels_0_dc702dc1a9f49492fdb7.jpg
2024-04-11 10:34:42,845 INFO    Thread-16 :5608 [dir_watcher.py:_on_file_created():271] file/dir created: E:\JD_PROJECT\project\ClassyVision\wandb\run-20240411_103431-657cbhcr\files\media
2024-04-11 10:34:42,845 INFO    Thread-16 :5608 [dir_watcher.py:_on_file_created():271] file/dir created: E:\JD_PROJECT\project\ClassyVision\wandb\run-20240411_103431-657cbhcr\files\media\images
2024-04-11 10:34:43,150 ERROR   wandb-upload_2:5608 [internal_api.py:upload_file():2767] upload_file exception https://storage.googleapis.com/wandb-production.appspot.com/beallhuang/YOLOv5/657cbhcr/media/images/Labels_0_dc702dc1a9f49492fdb7.jpg?Expires=1712889282&GoogleAccessId=gorilla-files-url-signer-man%40wandb-production.iam.gserviceaccount.com&Signature=pBZpctl%2BZLNS2eCYL13QoTPHoIMmJiCNVf6hL6g5qAHFLRwklGaPjjZ1rYxNxglfj0FaWPmRYv4Sl8Q64pWFilP9TlwKNlFdr4j83%2Fy%2FlFM%2BWGb%2FQQCsFh4bbETfu%2B1Wgu0hE3cFfuCuz2WdyYNzn%2BRxuoF0sW7KDAinXosO9HlmIwPKIMgKX6Jx93fYbkuLUmfZacMi3oyhWRUQpCrWWUqM%2BVubqq8jwkL4wq3HV1E2a2G7kst1N7MKUUvGUgp8hcDIahEtYU1%2F5Eg9v2nLAXv68Rj2PvHLHnw9M05bfqxyaG%2FAZrFV4dDz4B5e4y9S7JvjajFy7fLl3lT62i6zVA%3D%3D: ('Connection aborted.', ConnectionResetError(10054, '远程主机强迫关闭了一个现有的连接。', None, 10054, None))
2024-04-11 10:34:43,150 ERROR   wandb-upload_2:5608 [internal_api.py:upload_file():2769] upload_file request headers: {'User-Agent': 'python-requests/2.31.0', 'Accept-Encoding': 'gzip, deflate', 'Accept': '*/*', 'Connection': 'keep-alive', 'Content-Length': '161962'}
2024-04-11 10:34:43,150 ERROR   wandb-upload_2:5608 [internal_api.py:upload_file():2771] upload_file response body: 
2024-04-11 10:34:43,166 ERROR   wandb-upload_1:5608 [internal_api.py:upload_file():2767] upload_file exception https://storage.googleapis.com/wandb-production.appspot.com/beallhuang/YOLOv5/657cbhcr/media/images/Labels_0_7b7bbe6d6ad3ad4e2a51.jpg?Expires=1712889282&GoogleAccessId=gorilla-files-url-signer-man%40wandb-production.iam.gserviceaccount.com&Signature=AN%2F4ZUbuTWEaOT1NbH1FBwY6UiZuksm3SQ8VloqZtZuBw5qauEPEezw0djOTiUEM2YlvpSdf2Ej5%2Btd49DFM53jI4wqGSfuDrO49VMB6fXO5cKU6W5pbmjyFRmZbE%2B%2BoQtYZ3WkMRvfwRViZQ0iw7gWH000r9y7RKvIVBbBgN7uE%2FzNaKFeEexFqcgtBWkXoQfGCX6ycdaWsR5L05ODyZ%2FZ0ZOInXmjucMuwEA%2FI0You5ZDW%2F%2Bmv0iFBhlNyckO834Ch%2BKpTey%2Bq%2FXdgGPwMhD9Ad%2FI86LYgdAMXqkdeY6oDbLQ5oMqVViWXaOe%2BAAHj5y6uelGxD0kkGhkwP5SWqg%3D%3D: ('Connection aborted.', ConnectionResetError(10054, '远程主机强迫关闭了一个现有的连接。', None, 10054, None))
2024-04-11 10:34:43,166 ERROR   wandb-upload_1:5608 [internal_api.py:upload_file():2769] upload_file request headers: {'User-Agent': 'python-requests/2.31.0', 'Accept-Encoding': 'gzip, deflate', 'Accept': '*/*', 'Connection': 'keep-alive', 'Content-Length': '99194'}
2024-04-11 10:34:43,166 ERROR   wandb-upload_1:5608 [internal_api.py:upload_file():2771] upload_file response body: 
2024-04-11 10:34:43,214 ERROR   gpu       :5608 [interfaces.py:monitor():144] Failed to sample metric: Not Supported
2024-04-11 10:34:43,214 ERROR   gpu       :5608 [interfaces.py:monitor():144] Failed to sample metric: Not Supported
2024-04-11 10:34:43,846 INFO    Thread-16 :5608 [dir_watcher.py:_on_file_modified():288] file/dir modified: E:\JD_PROJECT\project\ClassyVision\wandb\run-20240411_103431-657cbhcr\files\output.log
2024-04-11 10:34:44,608 ERROR   wandb-upload_2:5608 [internal_api.py:upload_file():2767] upload_file exception https://storage.googleapis.com/wandb-production.appspot.com/beallhuang/YOLOv5/657cbhcr/media/images/Labels_0_dc702dc1a9f49492fdb7.jpg?Expires=1712889282&GoogleAccessId=gorilla-files-url-signer-man%40wandb-production.iam.gserviceaccount.com&Signature=pBZpctl%2BZLNS2eCYL13QoTPHoIMmJiCNVf6hL6g5qAHFLRwklGaPjjZ1rYxNxglfj0FaWPmRYv4Sl8Q64pWFilP9TlwKNlFdr4j83%2Fy%2FlFM%2BWGb%2FQQCsFh4bbETfu%2B1Wgu0hE3cFfuCuz2WdyYNzn%2BRxuoF0sW7KDAinXosO9HlmIwPKIMgKX6Jx93fYbkuLUmfZacMi3oyhWRUQpCrWWUqM%2BVubqq8jwkL4wq3HV1E2a2G7kst1N7MKUUvGUgp8hcDIahEtYU1%2F5Eg9v2nLAXv68Rj2PvHLHnw9M05bfqxyaG%2FAZrFV4dDz4B5e4y9S7JvjajFy7fLl3lT62i6zVA%3D%3D: ('Connection aborted.', ConnectionResetError(10054, '远程主机强迫关闭了一个现有的连接。', None, 10054, None))
2024-04-11 10:34:44,608 ERROR   wandb-upload_2:5608 [internal_api.py:upload_file():2769] upload_file request headers: {'User-Agent': 'python-requests/2.31.0', 'Accept-Encoding': 'gzip, deflate', 'Accept': '*/*', 'Connection': 'keep-alive', 'Content-Length': '161962'}
2024-04-11 10:34:44,608 ERROR   wandb-upload_2:5608 [internal_api.py:upload_file():2771] upload_file response body: 
2024-04-11 10:34:44,609 INFO    wandb-upload_2:5608 [retry.py:__call__():172] Retry attempt failed:
Traceback (most recent call last):
  File "D:\Users\Administrator\anaconda3\envs\ClassyVision2\lib\site-packages\urllib3\connectionpool.py", line 793, in urlopen
    response = self._make_request(
  File "D:\Users\Administrator\anaconda3\envs\ClassyVision2\lib\site-packages\urllib3\connectionpool.py", line 491, in _make_request
    raise new_e
  File "D:\Users\Administrator\anaconda3\envs\ClassyVision2\lib\site-packages\urllib3\connectionpool.py", line 467, in _make_request
    self._validate_conn(conn)
  File "D:\Users\Administrator\anaconda3\envs\ClassyVision2\lib\site-packages\urllib3\connectionpool.py", line 1099, in _validate_conn
    conn.connect()
  File "D:\Users\Administrator\anaconda3\envs\ClassyVision2\lib\site-packages\urllib3\connection.py", line 653, in connect
    sock_and_verified = _ssl_wrap_socket_and_match_hostname(
  File "D:\Users\Administrator\anaconda3\envs\ClassyVision2\lib\site-packages\urllib3\connection.py", line 806, in _ssl_wrap_socket_and_match_hostname
    ssl_sock = ssl_wrap_socket(
  File "D:\Users\Administrator\anaconda3\envs\ClassyVision2\lib\site-packages\urllib3\util\ssl_.py", line 465, in ssl_wrap_socket
    ssl_sock = _ssl_wrap_socket_impl(sock, context, tls_in_tls, server_hostname)
  File "D:\Users\Administrator\anaconda3\envs\ClassyVision2\lib\site-packages\urllib3\util\ssl_.py", line 509, in _ssl_wrap_socket_impl
    return ssl_context.wrap_socket(sock, server_hostname=server_hostname)
  File "D:\Users\Administrator\anaconda3\envs\ClassyVision2\lib\ssl.py", line 513, in wrap_socket
    return self.sslsocket_class._create(
  File "D:\Users\Administrator\anaconda3\envs\ClassyVision2\lib\ssl.py", line 1104, in _create
    self.do_handshake()
  File "D:\Users\Administrator\anaconda3\envs\ClassyVision2\lib\ssl.py", line 1375, in do_handshake
    self._sslobj.do_handshake()
ConnectionResetError: [WinError 10054] 远程主机强迫关闭了一个现有的连接。

During handling of the above exception, another exception occurred:

Traceback (most recent call last):
  File "D:\Users\Administrator\anaconda3\envs\ClassyVision2\lib\site-packages\requests\adapters.py", line 486, in send
    resp = conn.urlopen(
  File "D:\Users\Administrator\anaconda3\envs\ClassyVision2\lib\site-packages\urllib3\connectionpool.py", line 847, in urlopen
    retries = retries.increment(
  File "D:\Users\Administrator\anaconda3\envs\ClassyVision2\lib\site-packages\urllib3\util\retry.py", line 470, in increment
    raise reraise(type(error), error, _stacktrace)
  File "D:\Users\Administrator\anaconda3\envs\ClassyVision2\lib\site-packages\urllib3\util\util.py", line 38, in reraise
    raise value.with_traceback(tb)
  File "D:\Users\Administrator\anaconda3\envs\ClassyVision2\lib\site-packages\urllib3\connectionpool.py", line 793, in urlopen
    response = self._make_request(
  File "D:\Users\Administrator\anaconda3\envs\ClassyVision2\lib\site-packages\urllib3\connectionpool.py", line 491, in _make_request
    raise new_e
  File "D:\Users\Administrator\anaconda3\envs\ClassyVision2\lib\site-packages\urllib3\connectionpool.py", line 467, in _make_request
    self._validate_conn(conn)
  File "D:\Users\Administrator\anaconda3\envs\ClassyVision2\lib\site-packages\urllib3\connectionpool.py", line 1099, in _validate_conn
    conn.connect()
  File "D:\Users\Administrator\anaconda3\envs\ClassyVision2\lib\site-packages\urllib3\connection.py", line 653, in connect
    sock_and_verified = _ssl_wrap_socket_and_match_hostname(
  File "D:\Users\Administrator\anaconda3\envs\ClassyVision2\lib\site-packages\urllib3\connection.py", line 806, in _ssl_wrap_socket_and_match_hostname
    ssl_sock = ssl_wrap_socket(
  File "D:\Users\Administrator\anaconda3\envs\ClassyVision2\lib\site-packages\urllib3\util\ssl_.py", line 465, in ssl_wrap_socket
    ssl_sock = _ssl_wrap_socket_impl(sock, context, tls_in_tls, server_hostname)
  File "D:\Users\Administrator\anaconda3\envs\ClassyVision2\lib\site-packages\urllib3\util\ssl_.py", line 509, in _ssl_wrap_socket_impl
    return ssl_context.wrap_socket(sock, server_hostname=server_hostname)
  File "D:\Users\Administrator\anaconda3\envs\ClassyVision2\lib\ssl.py", line 513, in wrap_socket
    return self.sslsocket_class._create(
  File "D:\Users\Administrator\anaconda3\envs\ClassyVision2\lib\ssl.py", line 1104, in _create
    self.do_handshake()
  File "D:\Users\Administrator\anaconda3\envs\ClassyVision2\lib\ssl.py", line 1375, in do_handshake
    self._sslobj.do_handshake()
urllib3.exceptions.ProtocolError: ('Connection aborted.', ConnectionResetError(10054, '远程主机强迫关闭了一个现有的连接。', None, 10054, None))

During handling of the above exception, another exception occurred:

Traceback (most recent call last):
  File "D:\Users\Administrator\anaconda3\envs\ClassyVision2\lib\site-packages\wandb\sdk\internal\internal_api.py", line 2760, in upload_file
    response = self._upload_file_session.put(
  File "D:\Users\Administrator\anaconda3\envs\ClassyVision2\lib\site-packages\requests\sessions.py", line 649, in put
    return self.request("PUT", url, data=data, **kwargs)
  File "D:\Users\Administrator\anaconda3\envs\ClassyVision2\lib\site-packages\requests\sessions.py", line 589, in request
    resp = self.send(prep, **send_kwargs)
  File "D:\Users\Administrator\anaconda3\envs\ClassyVision2\lib\site-packages\requests\sessions.py", line 703, in send
    r = adapter.send(request, **kwargs)
  File "D:\Users\Administrator\anaconda3\envs\ClassyVision2\lib\site-packages\requests\adapters.py", line 501, in send
    raise ConnectionError(err, request=request)
requests.exceptions.ConnectionError: ('Connection aborted.', ConnectionResetError(10054, '远程主机强迫关闭了一个现有的连接。', None, 10054, None))

During handling of the above exception, another exception occurred:

Traceback (most recent call last):
  File "D:\Users\Administrator\anaconda3\envs\ClassyVision2\lib\site-packages\wandb\sdk\lib\retry.py", line 131, in __call__
    result = self._call_fn(*args, **kwargs)
  File "D:\Users\Administrator\anaconda3\envs\ClassyVision2\lib\site-packages\wandb\sdk\internal\internal_api.py", line 2791, in upload_file
    raise _e.with_traceback(sys.exc_info()[2])
  File "D:\Users\Administrator\anaconda3\envs\ClassyVision2\lib\site-packages\wandb\sdk\internal\internal_api.py", line 2760, in upload_file
    response = self._upload_file_session.put(
  File "D:\Users\Administrator\anaconda3\envs\ClassyVision2\lib\site-packages\requests\sessions.py", line 649, in put
    return self.request("PUT", url, data=data, **kwargs)
  File "D:\Users\Administrator\anaconda3\envs\ClassyVision2\lib\site-packages\requests\sessions.py", line 589, in request
    resp = self.send(prep, **send_kwargs)
  File "D:\Users\Administrator\anaconda3\envs\ClassyVision2\lib\site-packages\requests\sessions.py", line 703, in send
    r = adapter.send(request, **kwargs)
  File "D:\Users\Administrator\anaconda3\envs\ClassyVision2\lib\site-packages\requests\adapters.py", line 501, in send
    raise ConnectionError(err, request=request)
wandb.sdk.lib.retry.TransientError: None
2024-04-11 10:34:44,673 ERROR   wandb-upload_1:5608 [internal_api.py:upload_file():2767] upload_file exception https://storage.googleapis.com/wandb-production.appspot.com/beallhuang/YOLOv5/657cbhcr/media/images/Labels_0_7b7bbe6d6ad3ad4e2a51.jpg?Expires=1712889282&GoogleAccessId=gorilla-files-url-signer-man%40wandb-production.iam.gserviceaccount.com&Signature=AN%2F4ZUbuTWEaOT1NbH1FBwY6UiZuksm3SQ8VloqZtZuBw5qauEPEezw0djOTiUEM2YlvpSdf2Ej5%2Btd49DFM53jI4wqGSfuDrO49VMB6fXO5cKU6W5pbmjyFRmZbE%2B%2BoQtYZ3WkMRvfwRViZQ0iw7gWH000r9y7RKvIVBbBgN7uE%2FzNaKFeEexFqcgtBWkXoQfGCX6ycdaWsR5L05ODyZ%2FZ0ZOInXmjucMuwEA%2FI0You5ZDW%2F%2Bmv0iFBhlNyckO834Ch%2BKpTey%2Bq%2FXdgGPwMhD9Ad%2FI86LYgdAMXqkdeY6oDbLQ5oMqVViWXaOe%2BAAHj5y6uelGxD0kkGhkwP5SWqg%3D%3D: ('Connection aborted.', ConnectionResetError(10054, '远程主机强迫关闭了一个现有的连接。', None, 10054, None))
2024-04-11 10:34:44,673 ERROR   wandb-upload_1:5608 [internal_api.py:upload_file():2769] upload_file request headers: {'User-Agent': 'python-requests/2.31.0', 'Accept-Encoding': 'gzip, deflate', 'Accept': '*/*', 'Connection': 'keep-alive', 'Content-Length': '99194'}
2024-04-11 10:34:44,673 ERROR   wandb-upload_1:5608 [internal_api.py:upload_file():2771] upload_file response body: 
2024-04-11 10:34:44,673 INFO    wandb-upload_1:5608 [retry.py:__call__():172] Retry attempt failed:
Traceback (most recent call last):
  File "D:\Users\Administrator\anaconda3\envs\ClassyVision2\lib\site-packages\urllib3\connectionpool.py", line 793, in urlopen
    response = self._make_request(
  File "D:\Users\Administrator\anaconda3\envs\ClassyVision2\lib\site-packages\urllib3\connectionpool.py", line 491, in _make_request
    raise new_e
  File "D:\Users\Administrator\anaconda3\envs\ClassyVision2\lib\site-packages\urllib3\connectionpool.py", line 467, in _make_request
    self._validate_conn(conn)
  File "D:\Users\Administrator\anaconda3\envs\ClassyVision2\lib\site-packages\urllib3\connectionpool.py", line 1099, in _validate_conn
    conn.connect()
  File "D:\Users\Administrator\anaconda3\envs\ClassyVision2\lib\site-packages\urllib3\connection.py", line 653, in connect
    sock_and_verified = _ssl_wrap_socket_and_match_hostname(
  File "D:\Users\Administrator\anaconda3\envs\ClassyVision2\lib\site-packages\urllib3\connection.py", line 806, in _ssl_wrap_socket_and_match_hostname
    ssl_sock = ssl_wrap_socket(
  File "D:\Users\Administrator\anaconda3\envs\ClassyVision2\lib\site-packages\urllib3\util\ssl_.py", line 465, in ssl_wrap_socket
    ssl_sock = _ssl_wrap_socket_impl(sock, context, tls_in_tls, server_hostname)
  File "D:\Users\Administrator\anaconda3\envs\ClassyVision2\lib\site-packages\urllib3\util\ssl_.py", line 509, in _ssl_wrap_socket_impl
    return ssl_context.wrap_socket(sock, server_hostname=server_hostname)
  File "D:\Users\Administrator\anaconda3\envs\ClassyVision2\lib\ssl.py", line 513, in wrap_socket
    return self.sslsocket_class._create(
  File "D:\Users\Administrator\anaconda3\envs\ClassyVision2\lib\ssl.py", line 1104, in _create
    self.do_handshake()
  File "D:\Users\Administrator\anaconda3\envs\ClassyVision2\lib\ssl.py", line 1375, in do_handshake
    self._sslobj.do_handshake()
ConnectionResetError: [WinError 10054] 远程主机强迫关闭了一个现有的连接。

During handling of the above exception, another exception occurred:

Traceback (most recent call last):
  File "D:\Users\Administrator\anaconda3\envs\ClassyVision2\lib\site-packages\requests\adapters.py", line 486, in send
    resp = conn.urlopen(
  File "D:\Users\Administrator\anaconda3\envs\ClassyVision2\lib\site-packages\urllib3\connectionpool.py", line 847, in urlopen
    retries = retries.increment(
  File "D:\Users\Administrator\anaconda3\envs\ClassyVision2\lib\site-packages\urllib3\util\retry.py", line 470, in increment
    raise reraise(type(error), error, _stacktrace)
  File "D:\Users\Administrator\anaconda3\envs\ClassyVision2\lib\site-packages\urllib3\util\util.py", line 38, in reraise
    raise value.with_traceback(tb)
  File "D:\Users\Administrator\anaconda3\envs\ClassyVision2\lib\site-packages\urllib3\connectionpool.py", line 793, in urlopen
    response = self._make_request(
  File "D:\Users\Administrator\anaconda3\envs\ClassyVision2\lib\site-packages\urllib3\connectionpool.py", line 491, in _make_request
    raise new_e
  File "D:\Users\Administrator\anaconda3\envs\ClassyVision2\lib\site-packages\urllib3\connectionpool.py", line 467, in _make_request
    self._validate_conn(conn)
  File "D:\Users\Administrator\anaconda3\envs\ClassyVision2\lib\site-packages\urllib3\connectionpool.py", line 1099, in _validate_conn
    conn.connect()
  File "D:\Users\Administrator\anaconda3\envs\ClassyVision2\lib\site-packages\urllib3\connection.py", line 653, in connect
    sock_and_verified = _ssl_wrap_socket_and_match_hostname(
  File "D:\Users\Administrator\anaconda3\envs\ClassyVision2\lib\site-packages\urllib3\connection.py", line 806, in _ssl_wrap_socket_and_match_hostname
    ssl_sock = ssl_wrap_socket(
  File "D:\Users\Administrator\anaconda3\envs\ClassyVision2\lib\site-packages\urllib3\util\ssl_.py", line 465, in ssl_wrap_socket
    ssl_sock = _ssl_wrap_socket_impl(sock, context, tls_in_tls, server_hostname)
  File "D:\Users\Administrator\anaconda3\envs\ClassyVision2\lib\site-packages\urllib3\util\ssl_.py", line 509, in _ssl_wrap_socket_impl
    return ssl_context.wrap_socket(sock, server_hostname=server_hostname)
  File "D:\Users\Administrator\anaconda3\envs\ClassyVision2\lib\ssl.py", line 513, in wrap_socket
    return self.sslsocket_class._create(
  File "D:\Users\Administrator\anaconda3\envs\ClassyVision2\lib\ssl.py", line 1104, in _create
    self.do_handshake()
  File "D:\Users\Administrator\anaconda3\envs\ClassyVision2\lib\ssl.py", line 1375, in do_handshake
    self._sslobj.do_handshake()
urllib3.exceptions.ProtocolError: ('Connection aborted.', ConnectionResetError(10054, '远程主机强迫关闭了一个现有的连接。', None, 10054, None))

During handling of the above exception, another exception occurred:

Traceback (most recent call last):
  File "D:\Users\Administrator\anaconda3\envs\ClassyVision2\lib\site-packages\wandb\sdk\internal\internal_api.py", line 2760, in upload_file
    response = self._upload_file_session.put(
  File "D:\Users\Administrator\anaconda3\envs\ClassyVision2\lib\site-packages\requests\sessions.py", line 649, in put
    return self.request("PUT", url, data=data, **kwargs)
  File "D:\Users\Administrator\anaconda3\envs\ClassyVision2\lib\site-packages\requests\sessions.py", line 589, in request
    resp = self.send(prep, **send_kwargs)
  File "D:\Users\Administrator\anaconda3\envs\ClassyVision2\lib\site-packages\requests\sessions.py", line 703, in send
    r = adapter.send(request, **kwargs)
  File "D:\Users\Administrator\anaconda3\envs\ClassyVision2\lib\site-packages\requests\adapters.py", line 501, in send
    raise ConnectionError(err, request=request)
requests.exceptions.ConnectionError: ('Connection aborted.', ConnectionResetError(10054, '远程主机强迫关闭了一个现有的连接。', None, 10054, None))

During handling of the above exception, another exception occurred:

Traceback (most recent call last):
  File "D:\Users\Administrator\anaconda3\envs\ClassyVision2\lib\site-packages\wandb\sdk\lib\retry.py", line 131, in __call__
    result = self._call_fn(*args, **kwargs)
  File "D:\Users\Administrator\anaconda3\envs\ClassyVision2\lib\site-packages\wandb\sdk\internal\internal_api.py", line 2791, in upload_file
    raise _e.with_traceback(sys.exc_info()[2])
  File "D:\Users\Administrator\anaconda3\envs\ClassyVision2\lib\site-packages\wandb\sdk\internal\internal_api.py", line 2760, in upload_file
    response = self._upload_file_session.put(
  File "D:\Users\Administrator\anaconda3\envs\ClassyVision2\lib\site-packages\requests\sessions.py", line 649, in put
    return self.request("PUT", url, data=data, **kwargs)
  File "D:\Users\Administrator\anaconda3\envs\ClassyVision2\lib\site-packages\requests\sessions.py", line 589, in request
    resp = self.send(prep, **send_kwargs)
  File "D:\Users\Administrator\anaconda3\envs\ClassyVision2\lib\site-packages\requests\sessions.py", line 703, in send
    r = adapter.send(request, **kwargs)
  File "D:\Users\Administrator\anaconda3\envs\ClassyVision2\lib\site-packages\requests\adapters.py", line 501, in send
    raise ConnectionError(err, request=request)
wandb.sdk.lib.retry.TransientError: None
2024-04-11 10:34:45,230 ERROR   gpu       :5608 [interfaces.py:monitor():144] Failed to sample metric: Not Supported
2024-04-11 10:34:45,230 ERROR   gpu       :5608 [interfaces.py:monitor():144] Failed to sample metric: Not Supported
2024-04-11 10:34:46,977 ERROR   wandb-upload_2:5608 [internal_api.py:upload_file():2767] upload_file exception https://storage.googleapis.com/wandb-production.appspot.com/beallhuang/YOLOv5/657cbhcr/media/images/Labels_0_dc702dc1a9f49492fdb7.jpg?Expires=1712889282&GoogleAccessId=gorilla-files-url-signer-man%40wandb-production.iam.gserviceaccount.com&Signature=pBZpctl%2BZLNS2eCYL13QoTPHoIMmJiCNVf6hL6g5qAHFLRwklGaPjjZ1rYxNxglfj0FaWPmRYv4Sl8Q64pWFilP9TlwKNlFdr4j83%2Fy%2FlFM%2BWGb%2FQQCsFh4bbETfu%2B1Wgu0hE3cFfuCuz2WdyYNzn%2BRxuoF0sW7KDAinXosO9HlmIwPKIMgKX6Jx93fYbkuLUmfZacMi3oyhWRUQpCrWWUqM%2BVubqq8jwkL4wq3HV1E2a2G7kst1N7MKUUvGUgp8hcDIahEtYU1%2F5Eg9v2nLAXv68Rj2PvHLHnw9M05bfqxyaG%2FAZrFV4dDz4B5e4y9S7JvjajFy7fLl3lT62i6zVA%3D%3D: ('Connection aborted.', ConnectionResetError(10054, '远程主机强迫关闭了一个现有的连接。', None, 10054, None))
2024-04-11 10:34:46,977 ERROR   wandb-upload_2:5608 [internal_api.py:upload_file():2769] upload_file request headers: {'User-Agent': 'python-requests/2.31.0', 'Accept-Encoding': 'gzip, deflate', 'Accept': '*/*', 'Connection': 'keep-alive', 'Content-Length': '161962'}
2024-04-11 10:34:46,977 ERROR   wandb-upload_2:5608 [internal_api.py:upload_file():2771] upload_file response body: 
2024-04-11 10:34:47,056 ERROR   wandb-upload_1:5608 [internal_api.py:upload_file():2767] upload_file exception https://storage.googleapis.com/wandb-production.appspot.com/beallhuang/YOLOv5/657cbhcr/media/images/Labels_0_7b7bbe6d6ad3ad4e2a51.jpg?Expires=1712889282&GoogleAccessId=gorilla-files-url-signer-man%40wandb-production.iam.gserviceaccount.com&Signature=AN%2F4ZUbuTWEaOT1NbH1FBwY6UiZuksm3SQ8VloqZtZuBw5qauEPEezw0djOTiUEM2YlvpSdf2Ej5%2Btd49DFM53jI4wqGSfuDrO49VMB6fXO5cKU6W5pbmjyFRmZbE%2B%2BoQtYZ3WkMRvfwRViZQ0iw7gWH000r9y7RKvIVBbBgN7uE%2FzNaKFeEexFqcgtBWkXoQfGCX6ycdaWsR5L05ODyZ%2FZ0ZOInXmjucMuwEA%2FI0You5ZDW%2F%2Bmv0iFBhlNyckO834Ch%2BKpTey%2Bq%2FXdgGPwMhD9Ad%2FI86LYgdAMXqkdeY6oDbLQ5oMqVViWXaOe%2BAAHj5y6uelGxD0kkGhkwP5SWqg%3D%3D: ('Connection aborted.', ConnectionResetError(10054, '远程主机强迫关闭了一个现有的连接。', None, 10054, None))
2024-04-11 10:34:47,056 ERROR   wandb-upload_1:5608 [internal_api.py:upload_file():2769] upload_file request headers: {'User-Agent': 'python-requests/2.31.0', 'Accept-Encoding': 'gzip, deflate', 'Accept': '*/*', 'Connection': 'keep-alive', 'Content-Length': '99194'}
2024-04-11 10:34:47,057 ERROR   wandb-upload_1:5608 [internal_api.py:upload_file():2771] upload_file response body: 
2024-04-11 10:34:47,141 ERROR   wandb-upload_0:5608 [internal_api.py:upload_file():2767] upload_file exception https://storage.googleapis.com/wandb-production.appspot.com/beallhuang/YOLOv5/657cbhcr/wandb-metadata.json?Expires=1712889278&GoogleAccessId=gorilla-files-url-signer-man%40wandb-production.iam.gserviceaccount.com&Signature=km5e88YFw%2BgSlzDE2JKgWzM%2BizNHGVPy7KGY%2BfUXfTyX9uHqllWMVv%2FmDk0TAsvH8Ug81xJKejV%2FLcR1yO3WF6ETKIiyT34ZXlpDeL8B9l%2Bdr9k7irC1O4shi6ae0DGZPCq%2Fy1UeKDJGuHpnzSHWx6fPp46jmY6ePRrq0fN2vI2nGrney0zVGHc7nUC0Xs2HE98S26%2BkJeiOUokSg%2BATmbSY19ZFGLD2z2j9AL0wNJ%2Bo6KC5ZidGl4jINWVYsA7%2FgJoZwxzO7WzvdaYLDOVQJdbI0ABpkcenQmwjSBROgCXp2nX813eL0IJku6PWTiJIuXlx3nAcbnNzQKSBl8nJ6g%3D%3D: ('Connection aborted.', ConnectionResetError(10054, '远程主机强迫关闭了一个现有的连接。', None, 10054, None))
2024-04-11 10:34:47,141 ERROR   wandb-upload_0:5608 [internal_api.py:upload_file():2769] upload_file request headers: {'User-Agent': 'python-requests/2.31.0', 'Accept-Encoding': 'gzip, deflate', 'Accept': '*/*', 'Connection': 'keep-alive', 'Content-Length': '1342'}
2024-04-11 10:34:47,141 ERROR   wandb-upload_0:5608 [internal_api.py:upload_file():2771] upload_file response body: 
2024-04-11 10:34:47,244 ERROR   gpu       :5608 [interfaces.py:monitor():144] Failed to sample metric: Not Supported
2024-04-11 10:34:47,244 ERROR   gpu       :5608 [interfaces.py:monitor():144] Failed to sample metric: Not Supported
2024-04-11 10:34:47,564 DEBUG   HandlerThread:5608 [handler.py:handle_request():146] handle_request: status_report
2024-04-11 10:34:49,267 ERROR   gpu       :5608 [interfaces.py:monitor():144] Failed to sample metric: Not Supported
2024-04-11 10:34:49,267 ERROR   gpu       :5608 [interfaces.py:monitor():144] Failed to sample metric: Not Supported
2024-04-11 10:34:51,288 ERROR   gpu       :5608 [interfaces.py:monitor():144] Failed to sample metric: Not Supported
2024-04-11 10:34:51,289 ERROR   gpu       :5608 [interfaces.py:monitor():144] Failed to sample metric: Not Supported
2024-04-11 10:34:51,325 ERROR   wandb-upload_2:5608 [internal_api.py:upload_file():2767] upload_file exception https://storage.googleapis.com/wandb-production.appspot.com/beallhuang/YOLOv5/657cbhcr/media/images/Labels_0_dc702dc1a9f49492fdb7.jpg?Expires=1712889282&GoogleAccessId=gorilla-files-url-signer-man%40wandb-production.iam.gserviceaccount.com&Signature=pBZpctl%2BZLNS2eCYL13QoTPHoIMmJiCNVf6hL6g5qAHFLRwklGaPjjZ1rYxNxglfj0FaWPmRYv4Sl8Q64pWFilP9TlwKNlFdr4j83%2Fy%2FlFM%2BWGb%2FQQCsFh4bbETfu%2B1Wgu0hE3cFfuCuz2WdyYNzn%2BRxuoF0sW7KDAinXosO9HlmIwPKIMgKX6Jx93fYbkuLUmfZacMi3oyhWRUQpCrWWUqM%2BVubqq8jwkL4wq3HV1E2a2G7kst1N7MKUUvGUgp8hcDIahEtYU1%2F5Eg9v2nLAXv68Rj2PvHLHnw9M05bfqxyaG%2FAZrFV4dDz4B5e4y9S7JvjajFy7fLl3lT62i6zVA%3D%3D: ('Connection aborted.', ConnectionResetError(10054, '远程主机强迫关闭了一个现有的连接。', None, 10054, None))
2024-04-11 10:34:51,325 ERROR   wandb-upload_2:5608 [internal_api.py:upload_file():2769] upload_file request headers: {'User-Agent': 'python-requests/2.31.0', 'Accept-Encoding': 'gzip, deflate', 'Accept': '*/*', 'Connection': 'keep-alive', 'Content-Length': '161962'}
2024-04-11 10:34:51,325 ERROR   wandb-upload_2:5608 [internal_api.py:upload_file():2771] upload_file response body: 
2024-04-11 10:34:51,801 ERROR   wandb-upload_1:5608 [internal_api.py:upload_file():2767] upload_file exception https://storage.googleapis.com/wandb-production.appspot.com/beallhuang/YOLOv5/657cbhcr/media/images/Labels_0_7b7bbe6d6ad3ad4e2a51.jpg?Expires=1712889282&GoogleAccessId=gorilla-files-url-signer-man%40wandb-production.iam.gserviceaccount.com&Signature=AN%2F4ZUbuTWEaOT1NbH1FBwY6UiZuksm3SQ8VloqZtZuBw5qauEPEezw0djOTiUEM2YlvpSdf2Ej5%2Btd49DFM53jI4wqGSfuDrO49VMB6fXO5cKU6W5pbmjyFRmZbE%2B%2BoQtYZ3WkMRvfwRViZQ0iw7gWH000r9y7RKvIVBbBgN7uE%2FzNaKFeEexFqcgtBWkXoQfGCX6ycdaWsR5L05ODyZ%2FZ0ZOInXmjucMuwEA%2FI0You5ZDW%2F%2Bmv0iFBhlNyckO834Ch%2BKpTey%2Bq%2FXdgGPwMhD9Ad%2FI86LYgdAMXqkdeY6oDbLQ5oMqVViWXaOe%2BAAHj5y6uelGxD0kkGhkwP5SWqg%3D%3D: ('Connection aborted.', ConnectionResetError(10054, '远程主机强迫关闭了一个现有的连接。', None, 10054, None))
2024-04-11 10:34:51,801 ERROR   wandb-upload_1:5608 [internal_api.py:upload_file():2769] upload_file request headers: {'User-Agent': 'python-requests/2.31.0', 'Accept-Encoding': 'gzip, deflate', 'Accept': '*/*', 'Connection': 'keep-alive', 'Content-Length': '99194'}
2024-04-11 10:34:51,801 ERROR   wandb-upload_1:5608 [internal_api.py:upload_file():2771] upload_file response body: 
2024-04-11 10:34:52,607 DEBUG   HandlerThread:5608 [handler.py:handle_request():146] handle_request: status_report
2024-04-11 10:34:53,304 ERROR   gpu       :5608 [interfaces.py:monitor():144] Failed to sample metric: Not Supported
2024-04-11 10:34:53,304 ERROR   gpu       :5608 [interfaces.py:monitor():144] Failed to sample metric: Not Supported
2024-04-11 10:34:53,544 DEBUG   HandlerThread:5608 [handler.py:handle_request():146] handle_request: internal_messages
2024-04-11 10:34:53,559 DEBUG   HandlerThread:5608 [handler.py:handle_request():146] handle_request: stop_status
2024-04-11 10:34:53,559 DEBUG   SenderThread:5608 [sender.py:send_request():406] send_request: stop_status
2024-04-11 10:34:55,321 ERROR   gpu       :5608 [interfaces.py:monitor():144] Failed to sample metric: Not Supported
2024-04-11 10:34:55,321 ERROR   gpu       :5608 [interfaces.py:monitor():144] Failed to sample metric: Not Supported
2024-04-11 10:34:55,506 ERROR   wandb-upload_0:5608 [internal_api.py:upload_file():2767] upload_file exception https://storage.googleapis.com/wandb-production.appspot.com/beallhuang/YOLOv5/657cbhcr/wandb-metadata.json?Expires=1712889278&GoogleAccessId=gorilla-files-url-signer-man%40wandb-production.iam.gserviceaccount.com&Signature=km5e88YFw%2BgSlzDE2JKgWzM%2BizNHGVPy7KGY%2BfUXfTyX9uHqllWMVv%2FmDk0TAsvH8Ug81xJKejV%2FLcR1yO3WF6ETKIiyT34ZXlpDeL8B9l%2Bdr9k7irC1O4shi6ae0DGZPCq%2Fy1UeKDJGuHpnzSHWx6fPp46jmY6ePRrq0fN2vI2nGrney0zVGHc7nUC0Xs2HE98S26%2BkJeiOUokSg%2BATmbSY19ZFGLD2z2j9AL0wNJ%2Bo6KC5ZidGl4jINWVYsA7%2FgJoZwxzO7WzvdaYLDOVQJdbI0ABpkcenQmwjSBROgCXp2nX813eL0IJku6PWTiJIuXlx3nAcbnNzQKSBl8nJ6g%3D%3D: ('Connection aborted.', ConnectionResetError(10054, '远程主机强迫关闭了一个现有的连接。', None, 10054, None))
2024-04-11 10:34:55,506 ERROR   wandb-upload_0:5608 [internal_api.py:upload_file():2769] upload_file request headers: {'User-Agent': 'python-requests/2.31.0', 'Accept-Encoding': 'gzip, deflate', 'Accept': '*/*', 'Connection': 'keep-alive', 'Content-Length': '1342'}
2024-04-11 10:34:55,506 ERROR   wandb-upload_0:5608 [internal_api.py:upload_file():2771] upload_file response body: 
2024-04-11 10:34:57,334 ERROR   gpu       :5608 [interfaces.py:monitor():144] Failed to sample metric: Not Supported
2024-04-11 10:34:57,334 ERROR   gpu       :5608 [interfaces.py:monitor():144] Failed to sample metric: Not Supported
2024-04-11 10:34:57,918 DEBUG   HandlerThread:5608 [handler.py:handle_request():146] handle_request: status_report
2024-04-11 10:34:59,349 ERROR   gpu       :5608 [interfaces.py:monitor():144] Failed to sample metric: Not Supported
2024-04-11 10:34:59,349 ERROR   gpu       :5608 [interfaces.py:monitor():144] Failed to sample metric: Not Supported
2024-04-11 10:34:59,576 ERROR   wandb-upload_2:5608 [internal_api.py:upload_file():2767] upload_file exception https://storage.googleapis.com/wandb-production.appspot.com/beallhuang/YOLOv5/657cbhcr/media/images/Labels_0_dc702dc1a9f49492fdb7.jpg?Expires=1712889282&GoogleAccessId=gorilla-files-url-signer-man%40wandb-production.iam.gserviceaccount.com&Signature=pBZpctl%2BZLNS2eCYL13QoTPHoIMmJiCNVf6hL6g5qAHFLRwklGaPjjZ1rYxNxglfj0FaWPmRYv4Sl8Q64pWFilP9TlwKNlFdr4j83%2Fy%2FlFM%2BWGb%2FQQCsFh4bbETfu%2B1Wgu0hE3cFfuCuz2WdyYNzn%2BRxuoF0sW7KDAinXosO9HlmIwPKIMgKX6Jx93fYbkuLUmfZacMi3oyhWRUQpCrWWUqM%2BVubqq8jwkL4wq3HV1E2a2G7kst1N7MKUUvGUgp8hcDIahEtYU1%2F5Eg9v2nLAXv68Rj2PvHLHnw9M05bfqxyaG%2FAZrFV4dDz4B5e4y9S7JvjajFy7fLl3lT62i6zVA%3D%3D: ('Connection aborted.', ConnectionResetError(10054, '远程主机强迫关闭了一个现有的连接。', None, 10054, None))
2024-04-11 10:34:59,577 ERROR   wandb-upload_2:5608 [internal_api.py:upload_file():2769] upload_file request headers: {'User-Agent': 'python-requests/2.31.0', 'Accept-Encoding': 'gzip, deflate', 'Accept': '*/*', 'Connection': 'keep-alive', 'Content-Length': '161962'}
2024-04-11 10:34:59,577 ERROR   wandb-upload_2:5608 [internal_api.py:upload_file():2771] upload_file response body: 
2024-04-11 10:35:01,362 ERROR   gpu       :5608 [interfaces.py:monitor():144] Failed to sample metric: Not Supported
2024-04-11 10:35:01,362 ERROR   gpu       :5608 [interfaces.py:monitor():144] Failed to sample metric: Not Supported
2024-04-11 10:35:01,878 ERROR   wandb-upload_1:5608 [internal_api.py:upload_file():2767] upload_file exception https://storage.googleapis.com/wandb-production.appspot.com/beallhuang/YOLOv5/657cbhcr/media/images/Labels_0_7b7bbe6d6ad3ad4e2a51.jpg?Expires=1712889282&GoogleAccessId=gorilla-files-url-signer-man%40wandb-production.iam.gserviceaccount.com&Signature=AN%2F4ZUbuTWEaOT1NbH1FBwY6UiZuksm3SQ8VloqZtZuBw5qauEPEezw0djOTiUEM2YlvpSdf2Ej5%2Btd49DFM53jI4wqGSfuDrO49VMB6fXO5cKU6W5pbmjyFRmZbE%2B%2BoQtYZ3WkMRvfwRViZQ0iw7gWH000r9y7RKvIVBbBgN7uE%2FzNaKFeEexFqcgtBWkXoQfGCX6ycdaWsR5L05ODyZ%2FZ0ZOInXmjucMuwEA%2FI0You5ZDW%2F%2Bmv0iFBhlNyckO834Ch%2BKpTey%2Bq%2FXdgGPwMhD9Ad%2FI86LYgdAMXqkdeY6oDbLQ5oMqVViWXaOe%2BAAHj5y6uelGxD0kkGhkwP5SWqg%3D%3D: ('Connection aborted.', ConnectionResetError(10054, '远程主机强迫关闭了一个现有的连接。', None, 10054, None))
2024-04-11 10:35:01,879 ERROR   wandb-upload_1:5608 [internal_api.py:upload_file():2769] upload_file request headers: {'User-Agent': 'python-requests/2.31.0', 'Accept-Encoding': 'gzip, deflate', 'Accept': '*/*', 'Connection': 'keep-alive', 'Content-Length': '99194'}
2024-04-11 10:35:01,879 ERROR   wandb-upload_1:5608 [internal_api.py:upload_file():2771] upload_file response body: 
